<robot name="elevator_bot"><!-- Carriage Properties --><!-- <xacro:property name="example_property" value="-1" /> --><!-- 2in (0.0508m) line height --><!-- 1in (0.0254m) line width --><!-- 15.5 (0.3937m) width total --><!-- 47in (1.1938m) length total --><!-- 4.9748lbs (2.2565kgs) weight total --><!-- Specify some standard inertial calculations
    https://en.wikipedia.org/wiki/List_of_moments_of_inertia --><!-- These make use of xacro's mathematical functionality -->
    <material name="black">
        <color rgba="0.0 0.0 0.0 1.0" />
    </material>
    <material name="blue">
        <color rgba="0.13725490196078433 0.43137254901960786 0.5882352941176471 1.0" />
    </material>
    <material name="green">
        <color rgba="0.0 0.8 0.0 1.0" />
    </material>
    <material name="grey">
        <color rgba="0.2 0.2 0.2 1.0" />
    </material>
    <material name="yellow">
        <color rgba="1.0 0.8431372549019608 0.0 1" />
    </material>
    <material name="orange">
        <color rgba="0.9529411764705882 0.5294117647058824 0.1843137254901961 1" />
    </material>
    <material name="brown">
        <color rgba="0.8705882352941177 0.8117647058823529 0.7647058823529411 1.0" />
    </material>
    <material name="red">
        <color rgba="0.8 0.0 0.0 1.0" />
    </material>
    <material name="white">
        <color rgba="1.0 1.0 1.0 1.0" />
    </material>
    <material name="silver">
        <color rgba="0.700 0.700 0.700 1.000" />
    </material>
    <link name="base_link" />
    <link name="base_stage_link">
        <inertial>
            <origin rpy="0 0 0" xyz="0 0 0" />
            <mass value="2.2565" />
            <inertia ixx="0.4815465020833332" ixy="0.0" ixz="0.0" iyy="0.43779966888833327"
                iyz="0.0" izz="0.04471736888833333" />
        </inertial>
        <visual>
            <origin rpy="0 -1.5707963267948966 -1.5707963267948966" xyz="0 0 0.7625" />
            <geometry>
                <mesh filename="package://elevator_bot_description/meshes/BaseStageStructure.stl"
                    scale="0.001 0.001 0.001" />
            </geometry>
            <material name="blue" />
        </visual>
        <collision>
            <origin rpy="0 0 0" xyz="0 0 0" />
            <geometry>
                <box size="0.0508 1.525 0.485" />
            </geometry>
        </collision>
    </link>
    <joint name="base_stage_joint" type="fixed">
        <parent link="base_link" />
        <child link="base_stage_link" />
        <origin rpy="0 0 0" xyz="0 0 0" />
    </joint>

    <link name="second_stage_link">
        <inertial>
            <origin rpy="0 0 0" xyz="0 0 0" />
            <mass value="2.2565" />
            <inertia ixx="0.04471736888833333" ixy="0.0" ixz="0.0" iyy="0.43779966888833327"
                iyz="0.0" izz="0.4815465020833332" />
        </inertial><!-- All values here are
        completely made up. For your own sake, don't try to understand them -->
        <collision><!-- Top Bar -->
            <origin rpy="0 0 0" xyz="0 0 1.5127499999999998" />
            <geometry>
                <box size="0.485 0.0508 0.0265" />
            </geometry>
        </collision>
        <collision><!-- Bottom Bar -->
            <origin rpy="0 0 0" xyz="0 0 0.014249999999999999" />
            <geometry>
                <box size="0.485 0.0508 0.0265" />
            </geometry>
        </collision>
        <collision><!-- Left Bar -->
            <origin rpy="0 0 0" xyz="-0.2542 0 0.7635" />
            <geometry>
                <box size="0.0254 0.0508 1.525" />
            </geometry>
        </collision>
        <collision><!-- Right Bar -->
            <origin rpy="0 0 0" xyz="0.2542 0 0.7635" />
            <geometry>
                <box size="0.0254 0.0508 1.525" />
            </geometry>
        </collision>
        <visual>
            <origin rpy="0 0 0" xyz="-0.4065040650406504 -0.0254 -0.0625" /><!-- The model is *very
            slightly offset, even with @Nithin's model changes -->
            <geometry>
                <mesh filename="package://elevator_bot_description/meshes/2ndStageStructure.stl"
                    scale="0.001 0.001 0.001" />
            </geometry>
            <material name="blue" />
        </visual>
    </link>
    <joint name="base_stage_joint" type="continuous">
        <parent link="base_link" />
        <child link="second_stage_link" />
        <origin rpy="0 0 0" xyz="0 0 0" />
    </joint>

    <link name="carriage_stage_link">
        <inertial>
            <origin rpy="0 0 0" xyz="0 0 0" />
            <mass value="0.91740145454" />
            <inertia ixx="0.003936556836035837" ixy="0.0" ixz="0.0" iyy="0.010001593442589224"
                iyz="0.0" izz="0.013192146555586164" />
        </inertial>
        <visual>
            <origin rpy="0 0 0" xyz="0 0 0" />
            <geometry>
                <mesh filename="package://elevator_bot_description/meshes/CarriageStage.stl"
                    scale="0.001 0.001 0.001" />
            </geometry>
            <material name="blue" />
        </visual>
        <collision>
            <origin rpy="0 0 0" xyz="0 0.034925 0" />
            <geometry>
                <box size="0.3548888 0.2159 0.06985" />
            </geometry>
        </collision>
    </link>
    <joint name="second_stage_joint" type="prismatic">
        <parent link="base_stage_link" />
        <child link="carriage_stage_link" />
        <origin rpy="0 0 0" xyz="0 0 0" />
    </joint>
</robot>